<!-- Cartpole Model

    The state space is populated with joints in the order that they are
    defined in this file. The actuators also operate on joints.

    State-Space (name/joint/parameter):
        - cart      slider      position (m)
        - pole      hinge       angle (rad)
        - cart      slider      velocity (m/s)
        - pole      hinge       angular velocity (rad/s)

    Actuators (name/actuator/parameter):
        - cart      motor       force x (N)

-->
<mujoco model="inverted pendulum">
  <compiler coordinate="local" inertiafromgeom="true"/>
  <custom>
    <numeric data="2" name="frame_skip"/>
  </custom>
  <default>
    <joint armature="0" damping="1" limited="true"/>
    <geom contype="0" friction="1 0.1 0.1" rgba="0.7 0.7 0 1"/>
    <tendon/>
    <morot ctrlrange="-3 3"/>
  </default>
  <option gravity="0 0 -9.81" integrator="RK4" timestep="0.02"/>
  <size nstack="3000"/>
  <worldbody>
    <!--<geom name="floor" pos="0 0 -3.0" rgba="0.8 0.9 0.8 1" size="40 40 40" type="plane"/>/-->
    <geom name="rail" pos="0 0 0" quat="0.707 0 0.707 0" rgba="0.3 0.3 0.7 1" size="0.02 1" type="capsule"/>
    <body name="cart" pos="0 0 0">
      <joint axis="1 0 0" limited="true" name="slider" pos="0 0 0" range="-1 1" type="slide"/>
      <geom name="cart" pos="0 0 0" quat="0.707 0 0.707 0" size="0.1 0.1" type="capsule"/>
      <velocity>
        <linear x="10.0" y="10.0" z="10.0" xmin="-20.0" xmax="20.0" ymin="-20.0" ymax="20.0" zmin="-20.0" zmax="20.0"/>
        <angular x="0" y="0" z="0" xmin="-20.0" xmax="20.0" ymin="-20.0" ymax="20.0" zmin="-20.0" zmax="20.0"/>
      </velocity>
      <body name="pole" pos="0 0 0">
        <joint axis="0 1 0" name="hinge" pos="0 0 0" limited="false" range="-90 90" type="hinge"/>
        <geom fromto="0 0 0 0.001 0 0.6" name="cpole" rgba="0 0.7 0.7 1" size="0.049 0.3" type="capsule"/>
        <velocity>
          <linear x="0.0" y="0.0" z="0.0" xmin="-20.0" xmax="20.0" ymin="-20.0" ymax="20.0" zmin="-20.0" zmax="20.0"/>
          <angular x="0" y="0" z="0" xmin="-20.0" xmax="20.0" ymin="-20.0" ymax="20.0" zmin="-20.0" zmax="20.0"/>
        </velocity>
      </body>
    </body>
  </worldbody>
  <actuator>
    <motor gear="100" joint="slider" name="slide"/>
  </actuator>
</mujoco>

